Workbook

Sheet Start
A1: Opportunity Cost • Security
A3: A guided comparison of security work, protection and resources | Improved edition 6.2
A5: Start with one process, not the entire catalog. C001–C011 are examples; C012–C050 are prepared for live cases. Blue cells are inputs. Blank means unknown; a numeric 0 means confirmed zero.
A8: LIVE CASES | E8: APPROVED FORECASTS | I8: MEASURED / ELIGIBLE
A9: =COUNTIF(Cases!B7:B56,"Live") -> 0 | E9: =SUM(Checks!K7:K56) -> 0 | I9: =SUM(Checks!L7:L56) -> 0
A12: =IF(OR(COUNTBLANK('Review & Decision'!M7:M56)>0,COUNTBLANK(Checks!J7:J56)>0,COUNT(Checks!K7:K56)<50,COUNT(Checks!L7:L56)<50,COUNT(Checks!M7:M56)<50,COUNTIF(Checks!AG7:AG56,0)>0),"Integrity warning: missing readiness output or duplicate/missing key. Do not rely on planning totals.",IF(COUNTIF(Checks!AF7:AF56,"Missing measured evidence")>0,"Action required: one or more live Realized cases lack complete measurement evidence.","Readiness checks present. Examples, unchecked reviews and open decisions are excluded from live planning.")) -> Readiness checks present. Examples, unchecked reviews and open decisions are excluded from live planning.
A15: A clear path through one case
A16: =IFERROR(HYPERLINK("#'Case View'!A1","1 Explore / select a case"),"1 Explore / select a case") -> 1 Explore / select a case | E16: Read C001 as an example, then select C012 for your own case.
A18: =IFERROR(HYPERLINK("#'Cases'!C18","2 Define scope and proposal"),"2 Define scope and proposal") -> 2 Define scope and proposal | E18: Set type to Live. Name one process, owner, protection purpose and proposed change.
A20: =IFERROR(HYPERLINK("#'Current'!B18","3 Compare both profiles"),"3 Compare both profiles") -> 3 Compare both profiles | E20: Enter current and full proposed annual workload, cash costs, transition cost and sources.
A22: =IFERROR(HYPERLINK("#'Review & Decision'!B18","4 Review and approve"),"4 Review and approve") -> 4 Review and approve | E22: Record local evidence, clear the challenge review and approve an effective date.
A24: =IFERROR(HYPERLINK("#'Actuals'!B18","5 Measure; then plan"),"5 Measure; then plan") -> 5 Measure; then plan | E24: Add period-backed actual results when implemented. Reinvestment keeps cash separate.
A27: =IFERROR(HYPERLINK("#'Guide'!A1","Read the short user guide"),"Read the short user guide") -> Read the short user guide | E27: =IFERROR(HYPERLINK("#'Reinvestment'!A1","Open the live resource plan"),"Open the live resource plan") -> Open the live resource plan | I27: =IFERROR(HYPERLINK("#'Settings'!A1","Settings / workload helper"),"Settings / workload helper") -> Settings / workload helper
A29: Live portfolio — model potential is not an approved resource
A30: Annual change | E30: Modeled potential | G30: Approved forecast | I30: Measured | K30: Planning supply
A31: Business hours | E31: =SUMIFS(Checks!P7:P56,Checks!B7:B56,"Live",Checks!AH7:AH56,1) -> 0 | G31: =SUMIFS(Checks!P7:P56,Checks!K7:K56,1) -> 0 | I31: =SUMIFS(Checks!AL7:AL56,Checks!L7:L56,1) -> 0 | K31: =SUM(Checks!AA7:AA56) -> 0
A32: Specialist-team hours | E32: =SUMIFS(Checks!S7:S56,Checks!B7:B56,"Live",Checks!AH7:AH56,1) -> 0 | G32: =SUMIFS(Checks!S7:S56,Checks!K7:K56,1) -> 0 | I32: =SUMIFS(Checks!AM7:AM56,Checks!L7:L56,1) -> 0 | K32: =SUM(Checks!AB7:AB56) -> 0
A33: Recurring cash change | E33: =SUMIFS(Checks!V7:V56,Checks!B7:B56,"Live",Checks!AH7:AH56,1) -> 0 | G33: =SUMIFS(Checks!V7:V56,Checks!K7:K56,1) -> 0 | I33: =SUMIFS(Checks!AN7:AN56,Checks!L7:L56,1) -> 0 | K33: =SUM(Checks!AC7:AC56) -> 0
A34: Time-valued benefit • not cash | E34: =SUMIFS(Checks!Y7:Y56,Checks!B7:B56,"Live",Checks!AH7:AH56,1) -> 0 | G34: =SUMIFS(Checks!Y7:Y56,Checks!K7:K56,1) -> 0 | I34: =SUMIFS(Checks!AO7:AO56,Checks!L7:L56,1) -> 0 | K34: Not spendable
A35: One-time funding required | E35: =SUMIFS(Checks!Z7:Z56,Checks!B7:B56,"Live",Checks!AH7:AH56,1) -> 0 | G35: =SUMIFS(Checks!Z7:Z56,Checks!K7:K56,1) -> 0 | I35: Not future funding | K35: =SUM(Checks!AD7:AD56) -> 0
A38: Example portfolio — illustrative assumptions, excluded from the live plan
A39: Current annual cost | H39: =SUMIFS(Checks!W7:W56,Checks!B7:B56,"Example",Checks!AH7:AH56,1) -> 1423050
A40: Net business hours | H40: =SUMIFS(Checks!P7:P56,Checks!B7:B56,"Example",Checks!AH7:AH56,1) -> 14313.333
A41: Net specialist hours | H41: =SUMIFS(Checks!S7:S56,Checks!B7:B56,"Example",Checks!AH7:AH56,1) -> 1370
A42: Recurring cash change | H42: =SUMIFS(Checks!V7:V56,Checks!B7:B56,"Example",Checks!AH7:AH56,1) -> -97000
A43: Time-valued benefit | H43: =SUMIFS(Checks!Y7:Y56,Checks!B7:B56,"Example",Checks!AH7:AH56,1) -> 899050
A45: Capacity: 50 prepared case IDs and 20 demand rows. Tables support filtering and whole-table sorting; key-based links keep reviews attached to their cases. Adding arbitrary rows is not supported. Formulas are visibly separated but the workbook is not access-controlled: retain a baseline copy and do not overwrite calculated cells.

Sheet Case View
A1: Your case at a glance
A3: Select a case ID. This is a read-only summary; use the edit links below to enter data in its keyed input rows.
A5: =IFERROR(HYPERLINK("#'Start'!A1","← Start"),"← Start") -> ← Start | C5: C001 | E5: ="Case type: "&IF(COUNTIFS(Cases!$A$7:$A$56,$C$5,Cases!$B$7:$B$56,"<>")=1,IFERROR(INDEX(Cases!$B$7:$B$56,MATCH($C$5,Cases!$A$7:$A$56,0)),""),"") -> Case type: Example
A7: =IF(COUNTIFS(Checks!$A$7:$A$56,$C$5,Checks!$J$7:$J$56,"<>")=1,IFERROR(INDEX(Checks!$J$7:$J$56,MATCH($C$5,Checks!$A$7:$A$56,0)),""),"") -> Example only — never in live planning
A10: Scope and proposed change
A11: Activity | D11: =IF(COUNTIFS(Cases!$A$7:$A$56,$C$5,Cases!$C$7:$C$56,"<>")=1,IFERROR(INDEX(Cases!$C$7:$C$56,MATCH($C$5,Cases!$A$7:$A$56,0)),""),"") -> Document classification prompts
A13: Process / scope | D13: =IF(COUNTIFS(Cases!$A$7:$A$56,$C$5,Cases!$D$7:$D$56,"<>")=1,IFERROR(INDEX(Cases!$D$7:$D$56,MATCH($C$5,Cases!$A$7:$A$56,0)),""),"") -> Illustrative organization; replace with a precise local process.
A15: Protection purpose | D15: =IF(COUNTIFS(Cases!$A$7:$A$56,$C$5,Cases!$F$7:$F$56,"<>")=1,IFERROR(INDEX(Cases!$F$7:$F$56,MATCH($C$5,Cases!$A$7:$A$56,0)),""),"") -> Apply appropriate handling to sensitive information, including data leaving its original context.
A17: Chosen proposal | D17: =IF(COUNTIFS(Cases!$A$7:$A$56,$C$5,Cases!$G$7:$G$56,"<>")=1,IFERROR(INDEX(Cases!$G$7:$G$56,MATCH($C$5,Cases!$A$7:$A$56,0)),""),"") -> Replace
A19: Change / retained work | D19: =IF(COUNTIFS(Cases!$A$7:$A$56,$C$5,Cases!$H$7:$H$56,"<>")=1,IFERROR(INDEX(Cases!$H$7:$H$56,MATCH($C$5,Cases!$A$7:$A$56,0)),""),"") -> Full post-change operating profile; unchanged work is included.
A22: Annual comparison — current minus proposed; positive means a reduction
A23: Metric | E23: Current | G23: Proposed | I23: Change / benefit
A24: Business hours / year | E24: =IFERROR(INDEX(Checks!$N$7:$N$56,MATCH($C$5,Checks!$A$7:$A$56,0)),"") -> 7333.3333 | G24: =IFERROR(INDEX(Checks!$O$7:$O$56,MATCH($C$5,Checks!$A$7:$A$56,0)),"") -> 300 | I24: =IFERROR(INDEX(Checks!$P$7:$P$56,MATCH($C$5,Checks!$A$7:$A$56,0)),"") -> 7033.3333
A25: Specialist hours / year | E25: =IFERROR(INDEX(Checks!$Q$7:$Q$56,MATCH($C$5,Checks!$A$7:$A$56,0)),"") -> 150 | G25: =IFERROR(INDEX(Checks!$R$7:$R$56,MATCH($C$5,Checks!$A$7:$A$56,0)),"") -> 80 | I25: =IFERROR(INDEX(Checks!$S$7:$S$56,MATCH($C$5,Checks!$A$7:$A$56,0)),"") -> 70
A26: Recurring cash / year | E26: =IFERROR(INDEX(Checks!$T$7:$T$56,MATCH($C$5,Checks!$A$7:$A$56,0)),"") -> 0 | G26: =IFERROR(INDEX(Checks!$U$7:$U$56,MATCH($C$5,Checks!$A$7:$A$56,0)),"") -> 60000 | I26: =IFERROR(INDEX(Checks!$V$7:$V$56,MATCH($C$5,Checks!$A$7:$A$56,0)),"") -> -60000
A27: Cost including valued time / year | E27: =IFERROR(INDEX(Checks!$W$7:$W$56,MATCH($C$5,Checks!$A$7:$A$56,0)),"") -> 451250 | G27: =IFERROR(INDEX(Checks!$X$7:$X$56,MATCH($C$5,Checks!$A$7:$A$56,0)),"") -> 84000 | I27: =IFERROR(INDEX(Checks!$Y$7:$Y$56,MATCH($C$5,Checks!$A$7:$A$56,0)),"") -> 367250
A28: One-time implementation cost is additional. Time-valued benefit is not a cash saving. | I28: =IFERROR(INDEX(Checks!$Z$7:$Z$56,MATCH($C$5,Checks!$A$7:$A$56,0)),"") -> 40000
A31: Decision, evidence and actual measurement
A32: Local confidence | E32: Decision | I32: Benefit stage
A33: =IF(COUNTIFS('Review & Decision'!$A$7:$A$56,$C$5,'Review & Decision'!$B$7:$B$56,"<>")=1,IFERROR(INDEX('Review & Decision'!$B$7:$B$56,MATCH($C$5,'Review & Decision'!$A$7:$A$56,0)),""),"") -> Hypothesis | E33: =IF(COUNTIFS('Review & Decision'!$A$7:$A$56,$C$5,'Review & Decision'!$E$7:$E$56,"<>")=1,IFERROR(INDEX('Review & Decision'!$E$7:$E$56,MATCH($C$5,'Review & Decision'!$A$7:$A$56,0)),""),"") -> Open | I33: =IF(COUNTIFS('Review & Decision'!$A$7:$A$56,$C$5,'Review & Decision'!$H$7:$H$56,"<>")=1,IFERROR(INDEX('Review & Decision'!$H$7:$H$56,MATCH($C$5,'Review & Decision'!$A$7:$A$56,0)),""),"") -> Modeled
A35: Evidence reference | D35: =IF(COUNTIFS('Review & Decision'!$A$7:$A$56,$C$5,'Review & Decision'!$D$7:$D$56,"<>")=1,IFERROR(INDEX('Review & Decision'!$D$7:$D$56,MATCH($C$5,'Review & Decision'!$A$7:$A$56,0)),""),"") -> Illustrative scenario; no local validation.
A38: Challenge review | D38: =IF(COUNTIFS('Challenge Review'!$A$7:$A$56,$C$5,'Challenge Review'!$K$7:$K$56,"<>")=1,IFERROR(INDEX('Challenge Review'!$K$7:$K$56,MATCH($C$5,'Challenge Review'!$A$7:$A$56,0)),""),"") -> Unchecked
A41: Measurement status | D41: =IF(COUNTIFS(Actuals!$A$7:$A$56,$C$5,Actuals!$M$7:$M$56,"<>")=1,IFERROR(INDEX(Actuals!$M$7:$M$56,MATCH($C$5,Actuals!$A$7:$A$56,0)),""),"") -> Measurements incomplete
A44: Measured result | D44: =IF(IFERROR(INDEX(Checks!$I$7:$I$56,MATCH($C$5,Checks!$A$7:$A$56,0)),"")=1,"Measurements documented. See Actuals for signed changes, period and verification.","No complete, period-backed measurement is available.") -> No complete, period-backed measurement is available.
A47: Edit this case — links follow the case ID even after sorting
A48: =IFERROR(HYPERLINK("#'Cases'!C"&(MATCH($C$5,Cases!$A$7:$A$56,0)+6),"1 Scope and proposal"),"1 Scope and proposal") -> 1 Scope and proposal | E48: =IFERROR(HYPERLINK("#'Current'!B"&(MATCH($C$5,Current!$A$7:$A$56,0)+6),"2a Current profile"),"2a Current profile") -> 2a Current profile | I48: =IFERROR(HYPERLINK("#'Proposed'!B"&(MATCH($C$5,Proposed!$A$7:$A$56,0)+6),"2b Proposed profile"),"2b Proposed profile") -> 2b Proposed profile
A51: =IFERROR(HYPERLINK("#'Review & Decision'!B"&(MATCH($C$5,'Review & Decision'!$A$7:$A$56,0)+6),"3 Evidence / decision"),"3 Evidence / decision") -> 3 Evidence / decision | E51: =IFERROR(HYPERLINK("#'Challenge Review'!B"&(MATCH($C$5,'Challenge Review'!$A$7:$A$56,0)+6),"3b Challenge review"),"3b Challenge review") -> 3b Challenge review | I51: =IFERROR(HYPERLINK("#'Actuals'!B"&(MATCH($C$5,Actuals!$A$7:$A$56,0)+6),"4 Actual measurements"),"4 Actual measurements") -> 4 Actual measurements
A54: A workbook estimate does not authorize a control change. Confirm protection, obligations, rare-event exposure and a like-for-like alternative. Examples are hypotheses for comparison—not recommendations to retire the named controls.

Sheet Cases
A1: 01 Define the case
A3: Blue cells are editable. Use one activity in one process. Start a live case in C012; keep example records as Example.
A5: =IFERROR(HYPERLINK("#'Start'!A1","← Start"),"← Start") -> ← Start
A6: Case ID | B6: Case type | C6: Activity | D6: Process / scope | E6: Case owner | F6: Protection purpose | G6: Chosen proposal | H6: What changes / remains | I6: Assumptions / scope notes
A7: C001 | B7: Example | C7: Document classification prompts | D7: Illustrative organization; replace with a precise local process. | E7: Example only | F7: Apply appropriate handling to sensitive information, including data leaving its original context. | G7: Replace | H7: Full post-change operating profile; unchanged work is included. | I7: Illustrative, unvalidated assumptions migrated from the attached v5 workbook.
A8: C002 | B8: Example | C8: Periodic password changes | D8: Illustrative organization; replace with a precise local process. | E8: Example only | F8: Reduce the risk of compromised human authentication secrets. | G8: Replace | H8: Full post-change operating profile; unchanged work is included. | I8: Illustrative, unvalidated assumptions migrated from the attached v5 workbook.
A9: C003 | B9: Example | C9: Awareness training and phishing exercises | D9: Illustrative organization; replace with a precise local process. | E9: Example only | F9: Build relevant security capabilities, reliable reporting and appropriate responses. | G9: Simplify | H9: Full post-change operating profile; unchanged work is included. | I9: Illustrative, unvalidated assumptions migrated from the attached v5 workbook.
A10: C004 | B10: Example | C10: Quarterly access reviews | D10: Illustrative organization; replace with a precise local process. | E10: Example only | F10: Remove unnecessary access and identify inappropriate privileged access. | G10: Replace | H10: Full post-change operating profile; unchanged work is included. | I10: Illustrative, unvalidated assumptions migrated from the attached v5 workbook.
A11: C005 | B11: Example | C11: Supplier security questionnaires | D11: Illustrative organization; replace with a precise local process. | E11: Example only | F11: Understand and manage supplier access, exposure and operational dependency. | G11: Replace | H11: Full post-change operating profile; unchanged work is included. | I11: Illustrative, unvalidated assumptions migrated from the attached v5 workbook.
A12: C006 | B12: Example | C12: Vulnerability remediation prioritization | D12: Illustrative organization; replace with a precise local process. | E12: Example only | F12: Reduce exploitable weaknesses according to reachability and business consequences. | G12: Simplify | H12: Full post-change operating profile; unchanged work is included. | I12: Illustrative, unvalidated assumptions migrated from the attached v5 workbook.
A13: C007 | B13: Example | C13: Workplace access restrictions | D13: Illustrative organization; replace with a precise local process. | E13: Example only | F13: Limit unauthorized data movement and access while supporting legitimate work. | G13: Simplify | H13: Full post-change operating profile; unchanged work is included. | I13: Illustrative, unvalidated assumptions migrated from the attached v5 workbook.
A14: C008 | B14: Example | C14: Policy and risk assessment workshops | D14: Illustrative organization; replace with a precise local process. | E14: Example only | F14: Enable risk-informed decisions and communicate clear security expectations. | G14: Simplify | H14: Full post-change operating profile; unchanged work is included. | I14: Illustrative, unvalidated assumptions migrated from the attached v5 workbook.
A15: C009 | B15: Example | C15: Phishing-resistant authentication | D15: Illustrative organization; replace with a precise local process. | E15: Example only | F15: Resist credential theft and phishing-mediated account compromise. | G15: Retain | H15: Retain current protection and operating profile. | I15: Illustrative, unvalidated assumptions migrated from the attached v5 workbook.
A16: C010 | B16: Example | C16: Endpoint detection and response | D16: Illustrative organization; replace with a precise local process. | E16: Example only | F16: Detect and respond to compromise within a suitable operational window. | G16: Retain | H16: Retain current protection and operating profile. | I16: Illustrative, unvalidated assumptions migrated from the attached v5 workbook.
A17: C011 | B17: Example | C17: Critical-service recovery tests | D17: Illustrative organization; replace with a precise local process. | E17: Example only | F17: Demonstrate restoration of critical services under credible disruption scenarios. | G17: Retain | H17: Retain current protection and operating profile. | I17: Illustrative, unvalidated assumptions migrated from the attached v5 workbook.
A18: C012 | B18: Inactive
A19: C013 | B19: Inactive
A20: C014 | B20: Inactive
A21: C015 | B21: Inactive
A22: C016 | B22: Inactive
A23: C017 | B23: Inactive
A24: C018 | B24: Inactive
A25: C019 | B25: Inactive
A26: C020 | B26: Inactive
A27: C021 | B27: Inactive
A28: C022 | B28: Inactive
A29: C023 | B29: Inactive
... A56: C050 | B56: Inactive

Sheet Current
A1: 02a Current annual workload and cost
A3: Enter required annual figures and confirmed zeros. Cash means non-labor spend; employment cost is valued through hours. Execution hours apply to the selected group; additional specialist hours are separate.
A5: =IFERROR(HYPERLINK("#'Start'!A1","← Start"),"← Start") -> ← Start
A6: Case ID | B6: Execution group | C6: Execution h/year | D6: Additional specialist h/year | E6: Recurring cash €/year | F6: Estimate / measurement source | G6: Input status | H6: Business h/year | I6: Specialist h/year | J6: Time cost €/year | K6: Total cost €/year
A7: C001 | B7: Staff | C7: 7333.3333 | D7: 150 | E7: 0 | F7: Original example 1; annual hours retained from source. Not measured. | G7: =IF(AND(COUNT(C7:E7)=3,MIN(C7:E7)>=0,OR(B7="Staff",B7="Management",B7="Specialist"),LEN(TRIM(F7))>0,COUNT(Settings!$B$9:$B$11)=3,MIN(Settings!$B$9:$B$11)>=0),"Ready","Complete blue inputs") -> Ready | H7: =IF(G7="Ready",IF(B7="Specialist",0,C7),"") -> 7333.3333 | I7: =IF(G7="Ready",D7+IF(B7="Specialist",C7,0),"") -> 150 | J7: =IF(G7="Ready",C7*IF(B7="Staff",Settings!$B$9,IF(B7="Management",Settings!$B$10,Settings!$B$11))+D7*Settings!$B$11,"") -> 451250 | K7: =IF(G7="Ready",J7+E7,"") -> 451250
A8: C002 | B8: Staff | C8: 1733.3333 | D8: 0 | E8: 0 | F8: Original example 2; annual hours retained from source. Not measured. | G8: =IF(AND(COUNT(C8:E8)=3,MIN(C8:E8)>=0,OR(B8="Staff",B8="Management",B8="Specialist"),LEN(TRIM(F8))>0,COUNT(Settings!$B$9:$B$11)=3,MIN(Settings!$B$9:$B$11)>=0),"Ready","Complete blue inputs") -> Ready | H8: =IF(G8="Ready",IF(B8="Specialist",0,C8),"") -> 1733.3333 | I8: =IF(G8="Ready",D8+IF(B8="Specialist",C8,0),"") -> 0 | J8: =IF(G8="Ready",C8*IF(B8="Staff",Settings!$B$9,IF(B8="Management",Settings!$B$10,Settings!$B$11))+D8*Settings!$B$11,"") -> 104000 | K8: =IF(G8="Ready",J8+E8,"") -> 104000
A9: C003 | B9: Staff | C9: 2296.6667 | D9: 200 | E9: 0 | F9: Original example 3; annual hours retained from source. Not measured. | G9: =IF(AND(COUNT(C9:E9)=3,MIN(C9:E9)>=0,OR(B9="Staff",B9="Management",B9="Specialist"),LEN(TRIM(F9))>0,COUNT(Settings!$B$9:$B$11)=3,MIN(Settings!$B$9:$B$11)>=0),"Ready","Complete blue inputs") -> Ready | H9: =IF(G9="Ready",IF(B9="Specialist",0,C9),"") -> 2296.6667 | I9: =IF(G9="Ready",D9+IF(B9="Specialist",C9,0),"") -> 200 | J9: =IF(G9="Ready",C9*IF(B9="Staff",Settings!$B$9,IF(B9="Management",Settings!$B$10,Settings!$B$11))+D9*Settings!$B$11,"") -> 152800 | K9: =IF(G9="Ready",J9+E9,"") -> 152800
A10: C004 | B10: Management | C10: 800 | D10: 160 | E10: 0 | F10: Original example 4; annual hours retained from source. Not measured. | G10: =IF(AND(COUNT(C10:E10)=3,MIN(C10:E10)>=0,OR(B10="Staff",B10="Management",B10="Specialist"),LEN(TRIM(F10))>0,COUNT(Settings!$B$9:$B$11)=3,MIN(Settings!$B$9:$B$11)>=0),"Ready","Complete blue inputs") -> Ready | H10: =IF(G10="Ready",IF(B10="Specialist",0,C10),"") -> 800 | I10: =IF(G10="Ready",D10+IF(B10="Specialist",C10,0),"") -> 160 | J10: =IF(G10="Ready",C10*IF(B10="Staff",Settings!$B$9,IF(B10="Management",Settings!$B$10,Settings!$B$11))+D10*Settings!$B$11,"") -> 84000 | K10: =IF(G10="Ready",J10+E10,"") -> 84000
A11: C005 | B11: Specialist | C11: 500 | D11: 300 | E11: 0 | F11: Original example 5; annual hours retained from source. Not measured. | G11: =IF(AND(COUNT(C11:E11)=3,MIN(C11:E11)>=0,OR(B11="Staff",B11="Management",B11="Specialist"),LEN(TRIM(F11))>0,COUNT(Settings!$B$9:$B$11)=3,MIN(Settings!$B$9:$B$11)>=0),"Ready","Complete blue inputs") -> Ready | H11: =IF(G11="Ready",IF(B11="Specialist",0,C11),"") -> 0 | I11: =IF(G11="Ready",D11+IF(B11="Specialist",C11,0),"") -> 800 | J11: =IF(G11="Ready",C11*IF(B11="Staff",Settings!$B$9,IF(B11="Management",Settings!$B$10,Settings!$B$11))+D11*Settings!$B$11,"") -> 60000 | K11: =IF(G11="Ready",J11+E11,"") -> 60000
A12: C006 | B12: Specialist | C12: 1000 | D12: 400 | E12: 0 | F12: Original example 6; annual hours retained from source. Not measured. | G12: =IF(AND(COUNT(C12:E12)=3,MIN(C12:E12)>=0,OR(B12="Staff",B12="Management",B12="Specialist"),LEN(TRIM(F12))>0,COUNT(Settings!$B$9:$B$11)=3,MIN(Settings!$B$9:$B$11)>=0),"Ready","Complete blue inputs") -> Ready | H12: =IF(G12="Ready",IF(B12="Specialist",0,C12),"") -> 0 | I12: =IF(G12="Ready",D12+IF(B12="Specialist",C12,0),"") -> 1400 | J12: =IF(G12="Ready",C12*IF(B12="Staff",Settings!$B$9,IF(B12="Management",Settings!$B$10,Settings!$B$11))+D12*Settings!$B$11,"") -> 105000 | K12: =IF(G12="Ready",J12+E12,"") -> 105000
A13: C007 | B13: Staff | C13: 3300 | D13: 100 | E13: 0 | F13: Original example 7; annual hours retained from source. Not measured. | G13: =IF(AND(COUNT(C13:E13)=3,MIN(C13:E13)>=0,OR(B13="Staff",B13="Management",B13="Specialist"),LEN(TRIM(F13))>0,COUNT(Settings!$B$9:$B$11)=3,MIN(Settings!$B$9:$B$11)>=0),"Ready","Complete blue inputs") -> Ready | H13: =IF(G13="Ready",IF(B13="Specialist",0,C13),"") -> 3300 | I13: =IF(G13="Ready",D13+IF(B13="Specialist",C13,0),"") -> 100 | J13: =IF(G13="Ready",C13*IF(B13="Staff",Settings!$B$9,IF(B13="Management",Settings!$B$10,Settings!$B$11))+D13*Settings!$B$11,"") -> 205500 | K13: =IF(G13="Ready",J13+E13,"") -> 205500
A14: C008 | B14: Management | C14: 600 | D14: 120 | E14: 0 | F14: Original example 8; annual hours retained from source. Not measured. | G14: =IF(AND(COUNT(C14:E14)=3,MIN(C14:E14)>=0,OR(B14="Staff",B14="Management",B14="Specialist"),LEN(TRIM(F14))>0,COUNT(Settings!$B$9:$B$11)=3,MIN(Settings!$B$9:$B$11)>=0),"Ready","Complete blue inputs") -> Ready | H14: =IF(G14="Ready",IF(B14="Specialist",0,C14),"") -> 600 | I14: =IF(G14="Ready",D14+IF(B14="Specialist",C14,0),"") -> 120 | J14: =IF(G14="Ready",C14*IF(B14="Staff",Settings!$B$9,IF(B14="Management",Settings!$B$10,Settings!$B$11))+D14*Settings!$B$11,"") -> 63000 | K14: =IF(G14="Ready",J14+E14,"") -> 63000
A15: C009 | B15: Staff | C15: 1100 | D15: 80 | E15: 4000 | F15: Original example 9; annual hours retained from source. Not measured. | G15: =IF(AND(COUNT(C15:E15)=3,MIN(C15:E15)>=0,OR(B15="Staff",B15="Management",B15="Specialist"),LEN(TRIM(F15))>0,COUNT(Settings!$B$9:$B$11)=3,MIN(Settings!$B$9:$B$11)>=0),"Ready","Complete blue inputs") -> Ready | H15: =IF(G15="Ready",IF(B15="Specialist",0,C15),"") -> 1100 | I15: =IF(G15="Ready",D15+IF(B15="Specialist",C15,0),"") -> 80 | J15: =IF(G15="Ready",C15*IF(B15="Staff",Settings!$B$9,IF(B15="Management",Settings!$B$10,Settings!$B$11))+D15*Settings!$B$11,"") -> 72000 | K15: =IF(G15="Ready",J15+E15,"") -> 76000
A16: C010 | B16: Specialist | C16: 0 | D16: 300 | E16: 90000 | F16: Original example 10; annual hours retained from source. Not measured. | G16: =IF(AND(COUNT(C16:E16)=3,MIN(C16:E16)>=0,OR(B16="Staff",B16="Management",B16="Specialist"),LEN(TRIM(F16))>0,COUNT(Settings!$B$9:$B$11)=3,MIN(Settings!$B$9:$B$11)>=0),"Ready","Complete blue inputs") -> Ready | H16: =IF(G16="Ready",IF(B16="Specialist",0,C16),"") -> 0 | I16: =IF(G16="Ready",D16+IF(B16="Specialist",C16,0),"") -> 300 | J16: =IF(G16="Ready",C16*IF(B16="Staff",Settings!$B$9,IF(B16="Management",Settings!$B$10,Settings!$B$11))+D16*Settings!$B$11,"") -> 22500 | K16: =IF(G16="Ready",J16+E16,"") -> 112500
A17: C011 | B17: Specialist | C17: 0 | D17: 120 | E17: 0 | F17: Original example 11; annual hours retained from source. Not measured. | G17: =IF(AND(COUNT(C17:E17)=3,MIN(C17:E17)>=0,OR(B17="Staff",B17="Management",B17="Specialist"),LEN(TRIM(F17))>0,COUNT(Settings!$B$9:$B$11)=3,MIN(Settings!$B$9:$B$11)>=0),"Ready","Complete blue inputs") -> Ready | H17: =IF(G17="Ready",IF(B17="Specialist",0,C17),"") -> 0 | I17: =IF(G17="Ready",D17+IF(B17="Specialist",C17,0),"") -> 120 | J17: =IF(G17="Ready",C17*IF(B17="Staff",Settings!$B$9,IF(B17="Management",Settings!$B$10,Settings!$B$11))+D17*Settings!$B$11,"") -> 9000 | K17: =IF(G17="Ready",J17+E17,"") -> 9000
A18: C012 | G18: =IF(AND(COUNT(C18:E18)=3,MIN(C18:E18)>=0,OR(B18="Staff",B18="Management",B18="Specialist"),LEN(TRIM(F18))>0,COUNT(Settings!$B$9:$B$11)=3,MIN(Settings!$B$9:$B$11)>=0),"Ready","Complete blue inputs") -> Complete blue inputs | H18: =IF(G18="Ready",IF(B18="Specialist",0,C18),"") | I18: =IF(G18="Ready",D18+IF(B18="Specialist",C18,0),"") | J18: =IF(G18="Ready",C18*IF(B18="Staff",Settings!$B$9,IF(B18="Management",Settings!$B$10,Settings!$B$11))+D18*Settings!$B$11,"") | K18: =IF(G18="Ready",J18+E18,"")
A19: C013 | G19: =IF(AND(COUNT(C19:E19)=3,MIN(C19:E19)>=0,OR(B19="Staff",B19="Management",B19="Specialist"),LEN(TRIM(F19))>0,COUNT(Settings!$B$9:$B$11)=3,MIN(Settings!$B$9:$B$11)>=0),"Ready","Complete blue inputs") -> Complete blue inputs | H19: =IF(G19="Ready",IF(B19="Specialist",0,C19),"") | I19: =IF(G19="Ready",D19+IF(B19="Specialist",C19,0),"") | J19: =IF(G19="Ready",C19*IF(B19="Staff",Settings!$B$9,IF(B19="Management",Settings!$B$10,Settings!$B$11))+D19*Settings!$B$11,"") | K19: =IF(G19="Ready",J19+E19,"")
A20: C014 | G20: =IF(AND(COUNT(C20:E20)=3,MIN(C20:E20)>=0,OR(B20="Staff",B20="Management",B20="Specialist"),LEN(TRIM(F20))>0,COUNT(Settings!$B$9:$B$11)=3,MIN(Settings!$B$9:$B$11)>=0),"Ready","Complete blue inputs") -> Complete blue inputs | H20: =IF(G20="Ready",IF(B20="Specialist",0,C20),"") | I20: =IF(G20="Ready",D20+IF(B20="Specialist",C20,0),"") | J20: =IF(G20="Ready",C20*IF(B20="Staff",Settings!$B$9,IF(B20="Management",Settings!$B$10,Settings!$B$11))+D20*Settings!$B$11,"") | K20: =IF(G20="Ready",J20+E20,"")
A21: C015 | G21: =IF(AND(COUNT(C21:E21)=3,MIN(C21:E21)>=0,OR(B21="Staff",B21="Management",B21="Specialist"),LEN(TRIM(F21))>0,COUNT(Settings!$B$9:$B$11)=3,MIN(Settings!$B$9:$B$11)>=0),"Ready","Complete blue inputs") -> Complete blue inputs | H21: =IF(G21="Ready",IF(B21="Specialist",0,C21),"") | I21: =IF(G21="Ready",D21+IF(B21="Specialist",C21,0),"") | J21: =IF(G21="Ready",C21*IF(B21="Staff",Settings!$B$9,IF(B21="Management",Settings!$B$10,Settings!$B$11))+D21*Settings!$B$11,"") | K21: =IF(G21="Ready",J21+E21,"")
A22: C016 | G22: =IF(AND(COUNT(C22:E22)=3,MIN(C22:E22)>=0,OR(B22="Staff",B22="Management",B22="Specialist"),LEN(TRIM(F22))>0,COUNT(Settings!$B$9:$B$11)=3,MIN(Settings!$B$9:$B$11)>=0),"Ready","Complete blue inputs") -> Complete blue inputs | H22: =IF(G22="Ready",IF(B22="Specialist",0,C22),"") | I22: =IF(G22="Ready",D22+IF(B22="Specialist",C22,0),"") | J22: =IF(G22="Ready",C22*IF(B22="Staff",Settings!$B$9,IF(B22="Management",Settings!$B$10,Settings!$B$11))+D22*Settings!$B$11,"") | K22: =IF(G22="Ready",J22+E22,"")
A23: C017 | G23: =IF(AND(COUNT(C23:E23)=3,MIN(C23:E23)>=0,OR(B23="Staff",B23="Management",B23="Specialist"),LEN(TRIM(F23))>0,COUNT(Settings!$B$9:$B$11)=3,MIN(Settings!$B$9:$B$11)>=0),"Ready","Complete blue inputs") -> Complete blue inputs | H23: =IF(G23="Ready",IF(B23="Specialist",0,C23),"") | I23: =IF(G23="Ready",D23+IF(B23="Specialist",C23,0),"") | J23: =IF(G23="Ready",C23*IF(B23="Staff",Settings!$B$9,IF(B23="Management",Settings!$B$10,Settings!$B$11))+D23*Settings!$B$11,"") | K23: =IF(G23="Ready",J23+E23,"")
A24: C018 | G24: =IF(AND(COUNT(C24:E24)=3,MIN(C24:E24)>=0,OR(B24="Staff",B24="Management",B24="Specialist"),LEN(TRIM(F24))>0,COUNT(Settings!$B$9:$B$11)=3,MIN(Settings!$B$9:$B$11)>=0),"Ready","Complete blue inputs") -> Complete blue inputs | H24: =IF(G24="Ready",IF(B24="Specialist",0,C24),"") | I24: =IF(G24="Ready",D24+IF(B24="Specialist",C24,0),"") | J24: =IF(G24="Ready",C24*IF(B24="Staff",Settings!$B$9,IF(B24="Management",Settings!$B$10,Settings!$B$11))+D24*Settings!$B$11,"") | K24: =IF(G24="Ready",J24+E24,"")
A25: C019 | G25: =IF(AND(COUNT(C25:E25)=3,MIN(C25:E25)>=0,OR(B25="Staff",B25="Management",B25="Specialist"),LEN(TRIM(F25))>0,COUNT(Settings!$B$9:$B$11)=3,MIN(Settings!$B$9:$B$11)>=0),"Ready","Complete blue inputs") -> Complete blue inputs | H25: =IF(G25="Ready",IF(B25="Specialist",0,C25),"") | I25: =IF(G25="Ready",D25+IF(B25="Specialist",C25,0),"") | J25: =IF(G25="Ready",C25*IF(B25="Staff",Settings!$B$9,IF(B25="Management",Settings!$B$10,Settings!$B$11))+D25*Settings!$B$11,"") | K25: =IF(G25="Ready",J25+E25,"")
A26: C020 | G26: =IF(AND(COUNT(C26:E26)=3,MIN(C26:E26)>=0,OR(B26="Staff",B26="Management",B26="Specialist"),LEN(TRIM(F26))>0,COUNT(Settings!$B$9:$B$11)=3,MIN(Settings!$B$9:$B$11)>=0),"Ready","Complete blue inputs") -> Complete blue inputs | H26: =IF(G26="Ready",IF(B26="Specialist",0,C26),"") | I26: =IF(G26="Ready",D26+IF(B26="Specialist",C26,0),"") | J26: =IF(G26="Ready",C26*IF(B26="Staff",Settings!$B$9,IF(B26="Management",Settings!$B$10,Settings!$B$11))+D26*Settings!$B$11,"") | K26: =IF(G26="Ready",J26+E26,"")
A27: C021 | G27: =IF(AND(COUNT(C27:E27)=3,MIN(C27:E27)>=0,OR(B27="Staff",B27="Management",B27="Specialist"),LEN(TRIM(F27))>0,COUNT(Settings!$B$9:$B$11)=3,MIN(Settings!$B$9:$B$11)>=0),"Ready","Complete blue inputs") -> Complete blue inputs | H27: =IF(G27="Ready",IF(B27="Specialist",0,C27),"") | I27: =IF(G27="Ready",D27+IF(B27="Specialist",C27,0),"") | J27: =IF(G27="Ready",C27*IF(B27="Staff",Settings!$B$9,IF(B27="Management",Settings!$B$10,Settings!$B$11))+D27*Settings!$B$11,"") | K27: =IF(G27="Ready",J27+E27,"")
A28: C022 | G28: =IF(AND(COUNT(C28:E28)=3,MIN(C28:E28)>=0,OR(B28="Staff",B28="Management",B28="Specialist"),LEN(TRIM(F28))>0,COUNT(Settings!$B$9:$B$11)=3,MIN(Settings!$B$9:$B$11)>=0),"Ready","Complete blue inputs") -> Complete blue inputs | H28: =IF(G28="Ready",IF(B28="Specialist",0,C28),"") | I28: =IF(G28="Ready",D28+IF(B28="Specialist",C28,0),"") | J28: =IF(G28="Ready",C28*IF(B28="Staff",Settings!$B$9,IF(B28="Management",Settings!$B$10,Settings!$B$11))+D28*Settings!$B$11,"") | K28: =IF(G28="Ready",J28+E28,"")
A29: C023 | G29: =IF(AND(COUNT(C29:E29)=3,MIN(C29:E29)>=0,OR(B29="Staff",B29="Management",B29="Specialist"),LEN(TRIM(F29))>0,COUNT(Settings!$B$9:$B$11)=3,MIN(Settings!$B$9:$B$11)>=0),"Ready","Complete blue inputs") -> Complete blue inputs | H29: =IF(G29="Ready",IF(B29="Specialist",0,C29),"") | I29: =IF(G29="Ready",D29+IF(B29="Specialist",C29,0),"") | J29: =IF(G29="Ready",C29*IF(B29="Staff",Settings!$B$9,IF(B29="Management",Settings!$B$10,Settings!$B$11))+D29*Settings!$B$11,"") | K29: =IF(G29="Ready",J29+E29,"")
... A56: C050 | G56: =IF(AND(COUNT(C56:E56)=3,MIN(C56:E56)>=0,OR(B56="Staff",B56="Management",B56="Specialist"),LEN(TRIM(F56))>0,COUNT(Settings!$B$9:$B$11)=3,MIN(Settings!$B$9:$B$11)>=0),"Ready","Complete blue inputs") -> Complete blue inputs | H56: =IF(G56="Ready",IF(B56="Specialist",0,C56),"") | I56: =IF(G56="Ready",D56+IF(B56="Specialist",C56,0),"") | J56: =IF(G56="Ready",C56*IF(B56="Staff",Settings!$B$9,IF(B56="Management",Settings!$B$10,Settings!$B$11))+D56*Settings!$B$11,"") | K56: =IF(G56="Ready",J56+E56,"")

Sheet Proposed
A1: 02b Proposed annual workload and cost
A3: Enter the full post-change profile: unchanged work, fixed costs and transition effort. Cash means non-labor spend, not employment cost already valued through hours. No relevance score chooses the scenario.
A5: =IFERROR(HYPERLINK("#'Start'!A1","← Start"),"← Start") -> ← Start
A6: Case ID | B6: Execution group | C6: Execution h/year | D6: Additional specialist h/year | E6: Recurring cash €/year | F6: One-time cost € | G6: Estimate / measurement source | H6: Input status | I6: Business h/year | J6: Specialist h/year | K6: Time cost €/year | L6: Total cost €/year
A7: C001 | B7: Staff | C7: 300 | D7: 80 | E7: 60000 | F7: 40000 | G7: Original proposed example 1; assumed full annual profile. Not validated. | H7: =IF(AND(COUNT(C7:F7)=4,MIN(C7:F7)>=0,OR(B7="Staff",B7="Management",B7="Specialist"),LEN(TRIM(G7))>0,COUNT(Settings!$B$9:$B$11)=3,MIN(Settings!$B$9:$B$11)>=0),"Ready","Complete blue inputs") -> Ready | I7: =IF(H7="Ready",IF(B7="Specialist",0,C7),"") -> 300 | J7: =IF(H7="Ready",D7+IF(B7="Specialist",C7,0),"") -> 80 | K7: =IF(H7="Ready",C7*IF(B7="Staff",Settings!$B$9,IF(B7="Management",Settings!$B$10,Settings!$B$11))+D7*Settings!$B$11,"") -> 24000 | L7: =IF(H7="Ready",K7+E7,"") -> 84000
A8: C002 | B8: Staff | C8: 0 | D8: 10 | E8: 0 | F8: 5000 | G8: Original proposed example 2; assumed full annual profile. Not validated. | H8: =IF(AND(COUNT(C8:F8)=4,MIN(C8:F8)>=0,OR(B8="Staff",B8="Management",B8="Specialist"),LEN(TRIM(G8))>0,COUNT(Settings!$B$9:$B$11)=3,MIN(Settings!$B$9:$B$11)>=0),"Ready","Complete blue inputs") -> Ready | I8: =IF(H8="Ready",IF(B8="Specialist",0,C8),"") -> 0 | J8: =IF(H8="Ready",D8+IF(B8="Specialist",C8,0),"") -> 10 | K8: =IF(H8="Ready",C8*IF(B8="Staff",Settings!$B$9,IF(B8="Management",Settings!$B$10,Settings!$B$11))+D8*Settings!$B$11,"") -> 750 | L8: =IF(H8="Ready",K8+E8,"") -> 750
A9: C003 | B9: Staff | C9: 400 | D9: 60 | E9: 0 | F9: 5000 | G9: Original proposed example 3; assumed full annual profile. Not validated. | H9: =IF(AND(COUNT(C9:F9)=4,MIN(C9:F9)>=0,OR(B9="Staff",B9="Management",B9="Specialist"),LEN(TRIM(G9))>0,COUNT(Settings!$B$9:$B$11)=3,MIN(Settings!$B$9:$B$11)>=0),"Ready","Complete blue inputs") -> Ready | I9: =IF(H9="Ready",IF(B9="Specialist",0,C9),"") -> 400 | J9: =IF(H9="Ready",D9+IF(B9="Specialist",C9,0),"") -> 60 | K9: =IF(H9="Ready",C9*IF(B9="Staff",Settings!$B$9,IF(B9="Management",Settings!$B$10,Settings!$B$11))+D9*Settings!$B$11,"") -> 28500 | L9: =IF(H9="Ready",K9+E9,"") -> 28500
A10: C004 | B10: Management | C10: 100 | D10: 40 | E10: 15000 | F10: 25000 | G10: Original proposed example 4; assumed full annual profile. Not validated. | H10: =IF(AND(COUNT(C10:F10)=4,MIN(C10:F10)>=0,OR(B10="Staff",B10="Management",B10="Specialist"),LEN(TRIM(G10))>0,COUNT(Settings!$B$9:$B$11)=3,MIN(Settings!$B$9:$B$11)>=0),"Ready","Complete blue inputs") -> Ready | I10: =IF(H10="Ready",IF(B10="Specialist",0,C10),"") -> 100 | J10: =IF(H10="Ready",D10+IF(B10="Specialist",C10,0),"") -> 40 | K10: =IF(H10="Ready",C10*IF(B10="Staff",Settings!$B$9,IF(B10="Management",Settings!$B$10,Settings!$B$11))+D10*Settings!$B$11,"") -> 12000 | L10: =IF(H10="Ready",K10+E10,"") -> 27000
A11: C005 | B11: Specialist | C11: 50 | D11: 120 | E11: 10000 | F11: 8000 | G11: Original proposed example 5; assumed full annual profile. Not validated. | H11: =IF(AND(COUNT(C11:F11)=4,MIN(C11:F11)>=0,OR(B11="Staff",B11="Management",B11="Specialist"),LEN(TRIM(G11))>0,COUNT(Settings!$B$9:$B$11)=3,MIN(Settings!$B$9:$B$11)>=0),"Ready","Complete blue inputs") -> Ready | I11: =IF(H11="Ready",IF(B11="Specialist",0,C11),"") -> 0 | J11: =IF(H11="Ready",D11+IF(B11="Specialist",C11,0),"") -> 170 | K11: =IF(H11="Ready",C11*IF(B11="Staff",Settings!$B$9,IF(B11="Management",Settings!$B$10,Settings!$B$11))+D11*Settings!$B$11,"") -> 12750 | L11: =IF(H11="Ready",K11+E11,"") -> 22750
A12: C006 | B12: Specialist | C12: 800 | D12: 300 | E12: 0 | F12: 5000 | G12: Original proposed example 6; assumed full annual profile. Not validated. | H12: =IF(AND(COUNT(C12:F12)=4,MIN(C12:F12)>=0,OR(B12="Staff",B12="Management",B12="Specialist"),LEN(TRIM(G12))>0,COUNT(Settings!$B$9:$B$11)=3,MIN(Settings!$B$9:$B$11)>=0),"Ready","Complete blue inputs") -> Ready | I12: =IF(H12="Ready",IF(B12="Specialist",0,C12),"") -> 0 | J12: =IF(H12="Ready",D12+IF(B12="Specialist",C12,0),"") -> 1100 | K12: =IF(H12="Ready",C12*IF(B12="Staff",Settings!$B$9,IF(B12="Management",Settings!$B$10,Settings!$B$11))+D12*Settings!$B$11,"") -> 82500 | L12: =IF(H12="Ready",K12+E12,"") -> 82500
A13: C007 | B13: Staff | C13: 800 | D13: 60 | E13: 12000 | F13: 15000 | G13: Original proposed example 7; assumed full annual profile. Not validated. | H13: =IF(AND(COUNT(C13:F13)=4,MIN(C13:F13)>=0,OR(B13="Staff",B13="Management",B13="Specialist"),LEN(TRIM(G13))>0,COUNT(Settings!$B$9:$B$11)=3,MIN(Settings!$B$9:$B$11)>=0),"Ready","Complete blue inputs") -> Ready | I13: =IF(H13="Ready",IF(B13="Specialist",0,C13),"") -> 800 | J13: =IF(H13="Ready",D13+IF(B13="Specialist",C13,0),"") -> 60 | K13: =IF(H13="Ready",C13*IF(B13="Staff",Settings!$B$9,IF(B13="Management",Settings!$B$10,Settings!$B$11))+D13*Settings!$B$11,"") -> 52500 | L13: =IF(H13="Ready",K13+E13,"") -> 64500
A14: C008 | B14: Management | C14: 150 | D14: 40 | E14: 0 | F14: 2000 | G14: Original proposed example 8; assumed full annual profile. Not validated. | H14: =IF(AND(COUNT(C14:F14)=4,MIN(C14:F14)>=0,OR(B14="Staff",B14="Management",B14="Specialist"),LEN(TRIM(G14))>0,COUNT(Settings!$B$9:$B$11)=3,MIN(Settings!$B$9:$B$11)>=0),"Ready","Complete blue inputs") -> Ready | I14: =IF(H14="Ready",IF(B14="Specialist",0,C14),"") -> 150 | J14: =IF(H14="Ready",D14+IF(B14="Specialist",C14,0),"") -> 40 | K14: =IF(H14="Ready",C14*IF(B14="Staff",Settings!$B$9,IF(B14="Management",Settings!$B$10,Settings!$B$11))+D14*Settings!$B$11,"") -> 16500 | L14: =IF(H14="Ready",K14+E14,"") -> 16500
A15: C009 | B15: Staff | C15: 1100 | D15: 80 | E15: 4000 | F15: 0 | G15: Retain proposal: current annual profile carried forward; no assumed release. | H15: =IF(AND(COUNT(C15:F15)=4,MIN(C15:F15)>=0,OR(B15="Staff",B15="Management",B15="Specialist"),LEN(TRIM(G15))>0,COUNT(Settings!$B$9:$B$11)=3,MIN(Settings!$B$9:$B$11)>=0),"Ready","Complete blue inputs") -> Ready | I15: =IF(H15="Ready",IF(B15="Specialist",0,C15),"") -> 1100 | J15: =IF(H15="Ready",D15+IF(B15="Specialist",C15,0),"") -> 80 | K15: =IF(H15="Ready",C15*IF(B15="Staff",Settings!$B$9,IF(B15="Management",Settings!$B$10,Settings!$B$11))+D15*Settings!$B$11,"") -> 72000 | L15: =IF(H15="Ready",K15+E15,"") -> 76000
A16: C010 | B16: Specialist | C16: 0 | D16: 300 | E16: 90000 | F16: 0 | G16: Retain proposal: current annual profile carried forward; no assumed release. | H16: =IF(AND(COUNT(C16:F16)=4,MIN(C16:F16)>=0,OR(B16="Staff",B16="Management",B16="Specialist"),LEN(TRIM(G16))>0,COUNT(Settings!$B$9:$B$11)=3,MIN(Settings!$B$9:$B$11)>=0),"Ready","Complete blue inputs") -> Ready | I16: =IF(H16="Ready",IF(B16="Specialist",0,C16),"") -> 0 | J16: =IF(H16="Ready",D16+IF(B16="Specialist",C16,0),"") -> 300 | K16: =IF(H16="Ready",C16*IF(B16="Staff",Settings!$B$9,IF(B16="Management",Settings!$B$10,Settings!$B$11))+D16*Settings!$B$11,"") -> 22500 | L16: =IF(H16="Ready",K16+E16,"") -> 112500
A17: C011 | B17: Specialist | C17: 0 | D17: 120 | E17: 0 | F17: 0 | G17: Retain proposal: current annual profile carried forward; no assumed release. | H17: =IF(AND(COUNT(C17:F17)=4,MIN(C17:F17)>=0,OR(B17="Staff",B17="Management",B17="Specialist"),LEN(TRIM(G17))>0,COUNT(Settings!$B$9:$B$11)=3,MIN(Settings!$B$9:$B$11)>=0),"Ready","Complete blue inputs") -> Ready | I17: =IF(H17="Ready",IF(B17="Specialist",0,C17),"") -> 0 | J17: =IF(H17="Ready",D17+IF(B17="Specialist",C17,0),"") -> 120 | K17: =IF(H17="Ready",C17*IF(B17="Staff",Settings!$B$9,IF(B17="Management",Settings!$B$10,Settings!$B$11))+D17*Settings!$B$11,"") -> 9000 | L17: =IF(H17="Ready",K17+E17,"") -> 9000
A18: C012 | H18: =IF(AND(COUNT(C18:F18)=4,MIN(C18:F18)>=0,OR(B18="Staff",B18="Management",B18="Specialist"),LEN(TRIM(G18))>0,COUNT(Settings!$B$9:$B$11)=3,MIN(Settings!$B$9:$B$11)>=0),"Ready","Complete blue inputs") -> Complete blue inputs | I18: =IF(H18="Ready",IF(B18="Specialist",0,C18),"") | J18: =IF(H18="Ready",D18+IF(B18="Specialist",C18,0),"") | K18: =IF(H18="Ready",C18*IF(B18="Staff",Settings!$B$9,IF(B18="Management",Settings!$B$10,Settings!$B$11))+D18*Settings!$B$11,"") | L18: =IF(H18="Ready",K18+E18,"")
A19: C013 | H19: =IF(AND(COUNT(C19:F19)=4,MIN(C19:F19)>=0,OR(B19="Staff",B19="Management",B19="Specialist"),LEN(TRIM(G19))>0,COUNT(Settings!$B$9:$B$11)=3,MIN(Settings!$B$9:$B$11)>=0),"Ready","Complete blue inputs") -> Complete blue inputs | I19: =IF(H19="Ready",IF(B19="Specialist",0,C19),"") | J19: =IF(H19="Ready",D19+IF(B19="Specialist",C19,0),"") | K19: =IF(H19="Ready",C19*IF(B19="Staff",Settings!$B$9,IF(B19="Management",Settings!$B$10,Settings!$B$11))+D19*Settings!$B$11,"") | L19: =IF(H19="Ready",K19+E19,"")
A20: C014 | H20: =IF(AND(COUNT(C20:F20)=4,MIN(C20:F20)>=0,OR(B20="Staff",B20="Management",B20="Specialist"),LEN(TRIM(G20))>0,COUNT(Settings!$B$9:$B$11)=3,MIN(Settings!$B$9:$B$11)>=0),"Ready","Complete blue inputs") -> Complete blue inputs | I20: =IF(H20="Ready",IF(B20="Specialist",0,C20),"") | J20: =IF(H20="Ready",D20+IF(B20="Specialist",C20,0),"") | K20: =IF(H20="Ready",C20*IF(B20="Staff",Settings!$B$9,IF(B20="Management",Settings!$B$10,Settings!$B$11))+D20*Settings!$B$11,"") | L20: =IF(H20="Ready",K20+E20,"")
A21: C015 | H21: =IF(AND(COUNT(C21:F21)=4,MIN(C21:F21)>=0,OR(B21="Staff",B21="Management",B21="Specialist"),LEN(TRIM(G21))>0,COUNT(Settings!$B$9:$B$11)=3,MIN(Settings!$B$9:$B$11)>=0),"Ready","Complete blue inputs") -> Complete blue inputs | I21: =IF(H21="Ready",IF(B21="Specialist",0,C21),"") | J21: =IF(H21="Ready",D21+IF(B21="Specialist",C21,0),"") | K21: =IF(H21="Ready",C21*IF(B21="Staff",Settings!$B$9,IF(B21="Management",Settings!$B$10,Settings!$B$11))+D21*Settings!$B$11,"") | L21: =IF(H21="Ready",K21+E21,"")
A22: C016 | H22: =IF(AND(COUNT(C22:F22)=4,MIN(C22:F22)>=0,OR(B22="Staff",B22="Management",B22="Specialist"),LEN(TRIM(G22))>0,COUNT(Settings!$B$9:$B$11)=3,MIN(Settings!$B$9:$B$11)>=0),"Ready","Complete blue inputs") -> Complete blue inputs | I22: =IF(H22="Ready",IF(B22="Specialist",0,C22),"") | J22: =IF(H22="Ready",D22+IF(B22="Specialist",C22,0),"") | K22: =IF(H22="Ready",C22*IF(B22="Staff",Settings!$B$9,IF(B22="Management",Settings!$B$10,Settings!$B$11))+D22*Settings!$B$11,"") | L22: =IF(H22="Ready",K22+E22,"")
A23: C017 | H23: =IF(AND(COUNT(C23:F23)=4,MIN(C23:F23)>=0,OR(B23="Staff",B23="Management",B23="Specialist"),LEN(TRIM(G23))>0,COUNT(Settings!$B$9:$B$11)=3,MIN(Settings!$B$9:$B$11)>=0),"Ready","Complete blue inputs") -> Complete blue inputs | I23: =IF(H23="Ready",IF(B23="Specialist",0,C23),"") | J23: =IF(H23="Ready",D23+IF(B23="Specialist",C23,0),"") | K23: =IF(H23="Ready",C23*IF(B23="Staff",Settings!$B$9,IF(B23="Management",Settings!$B$10,Settings!$B$11))+D23*Settings!$B$11,"") | L23: =IF(H23="Ready",K23+E23,"")
A24: C018 | H24: =IF(AND(COUNT(C24:F24)=4,MIN(C24:F24)>=0,OR(B24="Staff",B24="Management",B24="Specialist"),LEN(TRIM(G24))>0,COUNT(Settings!$B$9:$B$11)=3,MIN(Settings!$B$9:$B$11)>=0),"Ready","Complete blue inputs") -> Complete blue inputs | I24: =IF(H24="Ready",IF(B24="Specialist",0,C24),"") | J24: =IF(H24="Ready",D24+IF(B24="Specialist",C24,0),"") | K24: =IF(H24="Ready",C24*IF(B24="Staff",Settings!$B$9,IF(B24="Management",Settings!$B$10,Settings!$B$11))+D24*Settings!$B$11,"") | L24: =IF(H24="Ready",K24+E24,"")
A25: C019 | H25: =IF(AND(COUNT(C25:F25)=4,MIN(C25:F25)>=0,OR(B25="Staff",B25="Management",B25="Specialist"),LEN(TRIM(G25))>0,COUNT(Settings!$B$9:$B$11)=3,MIN(Settings!$B$9:$B$11)>=0),"Ready","Complete blue inputs") -> Complete blue inputs | I25: =IF(H25="Ready",IF(B25="Specialist",0,C25),"") | J25: =IF(H25="Ready",D25+IF(B25="Specialist",C25,0),"") | K25: =IF(H25="Ready",C25*IF(B25="Staff",Settings!$B$9,IF(B25="Management",Settings!$B$10,Settings!$B$11))+D25*Settings!$B$11,"") | L25: =IF(H25="Ready",K25+E25,"")
A26: C020 | H26: =IF(AND(COUNT(C26:F26)=4,MIN(C26:F26)>=0,OR(B26="Staff",B26="Management",B26="Specialist"),LEN(TRIM(G26))>0,COUNT(Settings!$B$9:$B$11)=3,MIN(Settings!$B$9:$B$11)>=0),"Ready","Complete blue inputs") -> Complete blue inputs | I26: =IF(H26="Ready",IF(B26="Specialist",0,C26),"") | J26: =IF(H26="Ready",D26+IF(B26="Specialist",C26,0),"") | K26: =IF(H26="Ready",C26*IF(B26="Staff",Settings!$B$9,IF(B26="Management",Settings!$B$10,Settings!$B$11))+D26*Settings!$B$11,"") | L26: =IF(H26="Ready",K26+E26,"")
A27: C021 | H27: =IF(AND(COUNT(C27:F27)=4,MIN(C27:F27)>=0,OR(B27="Staff",B27="Management",B27="Specialist"),LEN(TRIM(G27))>0,COUNT(Settings!$B$9:$B$11)=3,MIN(Settings!$B$9:$B$11)>=0),"Ready","Complete blue inputs") -> Complete blue inputs | I27: =IF(H27="Ready",IF(B27="Specialist",0,C27),"") | J27: =IF(H27="Ready",D27+IF(B27="Specialist",C27,0),"") | K27: =IF(H27="Ready",C27*IF(B27="Staff",Settings!$B$9,IF(B27="Management",Settings!$B$10,Settings!$B$11))+D27*Settings!$B$11,"") | L27: =IF(H27="Ready",K27+E27,"")
A28: C022 | H28: =IF(AND(COUNT(C28:F28)=4,MIN(C28:F28)>=0,OR(B28="Staff",B28="Management",B28="Specialist"),LEN(TRIM(G28))>0,COUNT(Settings!$B$9:$B$11)=3,MIN(Settings!$B$9:$B$11)>=0),"Ready","Complete blue inputs") -> Complete blue inputs | I28: =IF(H28="Ready",IF(B28="Specialist",0,C28),"") | J28: =IF(H28="Ready",D28+IF(B28="Specialist",C28,0),"") | K28: =IF(H28="Ready",C28*IF(B28="Staff",Settings!$B$9,IF(B28="Management",Settings!$B$10,Settings!$B$11))+D28*Settings!$B$11,"") | L28: =IF(H28="Ready",K28+E28,"")
A29: C023 | H29: =IF(AND(COUNT(C29:F29)=4,MIN(C29:F29)>=0,OR(B29="Staff",B29="Management",B29="Specialist"),LEN(TRIM(G29))>0,COUNT(Settings!$B$9:$B$11)=3,MIN(Settings!$B$9:$B$11)>=0),"Ready","Complete blue inputs") -> Complete blue inputs | I29: =IF(H29="Ready",IF(B29="Specialist",0,C29),"") | J29: =IF(H29="Ready",D29+IF(B29="Specialist",C29,0),"") | K29: =IF(H29="Ready",C29*IF(B29="Staff",Settings!$B$9,IF(B29="Management",Settings!$B$10,Settings!$B$11))+D29*Settings!$B$11,"") | L29: =IF(H29="Ready",K29+E29,"")
... A56: C050 | H56: =IF(AND(COUNT(C56:F56)=4,MIN(C56:F56)>=0,OR(B56="Staff",B56="Management",B56="Specialist"),LEN(TRIM(G56))>0,COUNT(Settings!$B$9:$B$11)=3,MIN(Settings!$B$9:$B$11)>=0),"Ready","Complete blue inputs") -> Complete blue inputs | I56: =IF(H56="Ready",IF(B56="Specialist",0,C56),"") | J56: =IF(H56="Ready",D56+IF(B56="Specialist",C56,0),"") | K56: =IF(H56="Ready",C56*IF(B56="Staff",Settings!$B$9,IF(B56="Management",Settings!$B$10,Settings!$B$11))+D56*Settings!$B$11,"") | L56: =IF(H56="Ready",K56+E56,"")

Sheet Review & Decision
A1: 03 Review evidence and record the decision
A3: Planning needs positive approval, a cleared challenge review, local evidence and an effective date. A modeled hypothesis is not an allocatable resource.
A5: =IFERROR(HYPERLINK("#'Start'!A1","← Start"),"← Start") -> ← Start
A6: Case ID | B6: Confidence in local evidence | C6: Protection outcome | D6: Evidence / pilot reference | E6: Human decision | F6: Approver | G6: Decision date | H6: Benefit stage | I6: Effective / available from | J6: Usable business time % | K6: Usable specialist time % | L6: Risk acceptance reference | M6: Next action • calculated
A7: C001 | B7: Hypothesis | C7: Not assessed | D7: Illustrative scenario; no local validation. | E7: Open | H7: Modeled | J7: 0 | K7: 0 | M7: =IF(COUNTIFS(Checks!$A$7:$A$56,$A7,Checks!$J$7:$J$56,"<>")=1,IFERROR(INDEX(Checks!$J$7:$J$56,MATCH($A7,Checks!$A$7:$A$56,0)),""),"") -> Example only — never in live planning
A8: C002 | B8: Hypothesis | C8: Not assessed | D8: Illustrative scenario; no local validation. | E8: Open | H8: Modeled | J8: 0 | K8: 0 | M8: =IF(COUNTIFS(Checks!$A$7:$A$56,$A8,Checks!$J$7:$J$56,"<>")=1,IFERROR(INDEX(Checks!$J$7:$J$56,MATCH($A8,Checks!$A$7:$A$56,0)),""),"") -> Example only — never in live planning
A9: C003 | B9: Hypothesis | C9: Not assessed | D9: Illustrative scenario; no local validation. | E9: Open | H9: Modeled | J9: 0 | K9: 0 | M9: =IF(COUNTIFS(Checks!$A$7:$A$56,$A9,Checks!$J$7:$J$56,"<>")=1,IFERROR(INDEX(Checks!$J$7:$J$56,MATCH($A9,Checks!$A$7:$A$56,0)),""),"") -> Example only — never in live planning
A10: C004 | B10: Hypothesis | C10: Not assessed | D10: Illustrative scenario; no local validation. | E10: Open | H10: Modeled | J10: 0 | K10: 0 | M10: =IF(COUNTIFS(Checks!$A$7:$A$56,$A10,Checks!$J$7:$J$56,"<>")=1,IFERROR(INDEX(Checks!$J$7:$J$56,MATCH($A10,Checks!$A$7:$A$56,0)),""),"") -> Example only — never in live planning
A11: C005 | B11: Hypothesis | C11: Not assessed | D11: Illustrative scenario; no local validation. | E11: Open | H11: Modeled | J11: 0 | K11: 0 | M11: =IF(COUNTIFS(Checks!$A$7:$A$56,$A11,Checks!$J$7:$J$56,"<>")=1,IFERROR(INDEX(Checks!$J$7:$J$56,MATCH($A11,Checks!$A$7:$A$56,0)),""),"") -> Example only — never in live planning
A12: C006 | B12: Hypothesis | C12: Not assessed | D12: Illustrative scenario; no local validation. | E12: Open | H12: Modeled | J12: 0 | K12: 0 | M12: =IF(COUNTIFS(Checks!$A$7:$A$56,$A12,Checks!$J$7:$J$56,"<>")=1,IFERROR(INDEX(Checks!$J$7:$J$56,MATCH($A12,Checks!$A$7:$A$56,0)),""),"") -> Example only — never in live planning
A13: C007 | B13: Hypothesis | C13: Not assessed | D13: Illustrative scenario; no local validation. | E13: Open | H13: Modeled | J13: 0 | K13: 0 | M13: =IF(COUNTIFS(Checks!$A$7:$A$56,$A13,Checks!$J$7:$J$56,"<>")=1,IFERROR(INDEX(Checks!$J$7:$J$56,MATCH($A13,Checks!$A$7:$A$56,0)),""),"") -> Example only — never in live planning
A14: C008 | B14: Hypothesis | C14: Not assessed | D14: Illustrative scenario; no local validation. | E14: Open | H14: Modeled | J14: 0 | K14: 0 | M14: =IF(COUNTIFS(Checks!$A$7:$A$56,$A14,Checks!$J$7:$J$56,"<>")=1,IFERROR(INDEX(Checks!$J$7:$J$56,MATCH($A14,Checks!$A$7:$A$56,0)),""),"") -> Example only — never in live planning
A15: C009 | B15: Hypothesis | C15: Not assessed | D15: Illustrative scenario; no local validation. | E15: Open | H15: Modeled | J15: 0 | K15: 0 | M15: =IF(COUNTIFS(Checks!$A$7:$A$56,$A15,Checks!$J$7:$J$56,"<>")=1,IFERROR(INDEX(Checks!$J$7:$J$56,MATCH($A15,Checks!$A$7:$A$56,0)),""),"") -> Example only — never in live planning
A16: C010 | B16: Hypothesis | C16: Not assessed | D16: Illustrative scenario; no local validation. | E16: Open | H16: Modeled | J16: 0 | K16: 0 | M16: =IF(COUNTIFS(Checks!$A$7:$A$56,$A16,Checks!$J$7:$J$56,"<>")=1,IFERROR(INDEX(Checks!$J$7:$J$56,MATCH($A16,Checks!$A$7:$A$56,0)),""),"") -> Example only — never in live planning
A17: C011 | B17: Hypothesis | C17: Not assessed | D17: Illustrative scenario; no local validation. | E17: Open | H17: Modeled | J17: 0 | K17: 0 | M17: =IF(COUNTIFS(Checks!$A$7:$A$56,$A17,Checks!$J$7:$J$56,"<>")=1,IFERROR(INDEX(Checks!$J$7:$J$56,MATCH($A17,Checks!$A$7:$A$56,0)),""),"") -> Example only — never in live planning
A18: C012 | M18: =IF(COUNTIFS(Checks!$A$7:$A$56,$A18,Checks!$J$7:$J$56,"<>")=1,IFERROR(INDEX(Checks!$J$7:$J$56,MATCH($A18,Checks!$A$7:$A$56,0)),""),"") -> Unused slot
A19: C013 | M19: =IF(COUNTIFS(Checks!$A$7:$A$56,$A19,Checks!$J$7:$J$56,"<>")=1,IFERROR(INDEX(Checks!$J$7:$J$56,MATCH($A19,Checks!$A$7:$A$56,0)),""),"") -> Unused slot
A20: C014 | M20: =IF(COUNTIFS(Checks!$A$7:$A$56,$A20,Checks!$J$7:$J$56,"<>")=1,IFERROR(INDEX(Checks!$J$7:$J$56,MATCH($A20,Checks!$A$7:$A$56,0)),""),"") -> Unused slot
A21: C015 | M21: =IF(COUNTIFS(Checks!$A$7:$A$56,$A21,Checks!$J$7:$J$56,"<>")=1,IFERROR(INDEX(Checks!$J$7:$J$56,MATCH($A21,Checks!$A$7:$A$56,0)),""),"") -> Unused slot
A22: C016 | M22: =IF(COUNTIFS(Checks!$A$7:$A$56,$A22,Checks!$J$7:$J$56,"<>")=1,IFERROR(INDEX(Checks!$J$7:$J$56,MATCH($A22,Checks!$A$7:$A$56,0)),""),"") -> Unused slot
A23: C017 | M23: =IF(COUNTIFS(Checks!$A$7:$A$56,$A23,Checks!$J$7:$J$56,"<>")=1,IFERROR(INDEX(Checks!$J$7:$J$56,MATCH($A23,Checks!$A$7:$A$56,0)),""),"") -> Unused slot
A24: C018 | M24: =IF(COUNTIFS(Checks!$A$7:$A$56,$A24,Checks!$J$7:$J$56,"<>")=1,IFERROR(INDEX(Checks!$J$7:$J$56,MATCH($A24,Checks!$A$7:$A$56,0)),""),"") -> Unused slot
A25: C019 | M25: =IF(COUNTIFS(Checks!$A$7:$A$56,$A25,Checks!$J$7:$J$56,"<>")=1,IFERROR(INDEX(Checks!$J$7:$J$56,MATCH($A25,Checks!$A$7:$A$56,0)),""),"") -> Unused slot
A26: C020 | M26: =IF(COUNTIFS(Checks!$A$7:$A$56,$A26,Checks!$J$7:$J$56,"<>")=1,IFERROR(INDEX(Checks!$J$7:$J$56,MATCH($A26,Checks!$A$7:$A$56,0)),""),"") -> Unused slot
A27: C021 | M27: =IF(COUNTIFS(Checks!$A$7:$A$56,$A27,Checks!$J$7:$J$56,"<>")=1,IFERROR(INDEX(Checks!$J$7:$J$56,MATCH($A27,Checks!$A$7:$A$56,0)),""),"") -> Unused slot
A28: C022 | M28: =IF(COUNTIFS(Checks!$A$7:$A$56,$A28,Checks!$J$7:$J$56,"<>")=1,IFERROR(INDEX(Checks!$J$7:$J$56,MATCH($A28,Checks!$A$7:$A$56,0)),""),"") -> Unused slot
A29: C023 | M29: =IF(COUNTIFS(Checks!$A$7:$A$56,$A29,Checks!$J$7:$J$56,"<>")=1,IFERROR(INDEX(Checks!$J$7:$J$56,MATCH($A29,Checks!$A$7:$A$56,0)),""),"") -> Unused slot
... A56: C050 | M56: =IF(COUNTIFS(Checks!$A$7:$A$56,$A56,Checks!$J$7:$J$56,"<>")=1,IFERROR(INDEX(Checks!$J$7:$J$56,MATCH($A56,Checks!$A$7:$A$56,0)),""),"") -> Unused slot

Sheet Challenge Review
A1: 03b Challenge the proposal
A3: Answer Yes only after checking. No or an unresolved concern blocks planning. Unchecked is not approval. Review the purpose, rare failures and skills—not just the arithmetic.
A5: =IFERROR(HYPERLINK("#'Start'!A1","← Start"),"← Start") -> ← Start
A6: Case ID | B6: Reviewer | C6: Review date | D6: Protection purpose checked | E6: Full alternative cost checked | F6: Binding requirements checked | G6: Rare failures / defense depth checked | H6: Overlap / double count checked | I6: Capacity skills and timing checked | J6: Unresolved concern | K6: Review result
A7: C001 | D7: Unchecked | E7: Unchecked | F7: Unchecked | G7: Unchecked | H7: Unchecked | I7: Unchecked | K7: =IF(OR(COUNTIF(D7:I7,"No")>0,LEN(TRIM(J7))>0),"Blocked",IF(AND(COUNTIF(D7:I7,"Yes")=6,LEN(TRIM(B7))>0,ISNUMBER(C7),C7>0,C7<=Settings!$B$7),"Clear","Unchecked")) -> Unchecked
A8: C002 | D8: Unchecked | E8: Unchecked | F8: Unchecked | G8: Unchecked | H8: Unchecked | I8: Unchecked | K8: =IF(OR(COUNTIF(D8:I8,"No")>0,LEN(TRIM(J8))>0),"Blocked",IF(AND(COUNTIF(D8:I8,"Yes")=6,LEN(TRIM(B8))>0,ISNUMBER(C8),C8>0,C8<=Settings!$B$7),"Clear","Unchecked")) -> Unchecked
A9: C003 | D9: Unchecked | E9: Unchecked | F9: Unchecked | G9: Unchecked | H9: Unchecked | I9: Unchecked | K9: =IF(OR(COUNTIF(D9:I9,"No")>0,LEN(TRIM(J9))>0),"Blocked",IF(AND(COUNTIF(D9:I9,"Yes")=6,LEN(TRIM(B9))>0,ISNUMBER(C9),C9>0,C9<=Settings!$B$7),"Clear","Unchecked")) -> Unchecked
A10: C004 | D10: Unchecked | E10: Unchecked | F10: Unchecked | G10: Unchecked | H10: Unchecked | I10: Unchecked | K10: =IF(OR(COUNTIF(D10:I10,"No")>0,LEN(TRIM(J10))>0),"Blocked",IF(AND(COUNTIF(D10:I10,"Yes")=6,LEN(TRIM(B10))>0,ISNUMBER(C10),C10>0,C10<=Settings!$B$7),"Clear","Unchecked")) -> Unchecked
A11: C005 | D11: Unchecked | E11: Unchecked | F11: Unchecked | G11: Unchecked | H11: Unchecked | I11: Unchecked | K11: =IF(OR(COUNTIF(D11:I11,"No")>0,LEN(TRIM(J11))>0),"Blocked",IF(AND(COUNTIF(D11:I11,"Yes")=6,LEN(TRIM(B11))>0,ISNUMBER(C11),C11>0,C11<=Settings!$B$7),"Clear","Unchecked")) -> Unchecked
A12: C006 | D12: Unchecked | E12: Unchecked | F12: Unchecked | G12: Unchecked | H12: Unchecked | I12: Unchecked | K12: =IF(OR(COUNTIF(D12:I12,"No")>0,LEN(TRIM(J12))>0),"Blocked",IF(AND(COUNTIF(D12:I12,"Yes")=6,LEN(TRIM(B12))>0,ISNUMBER(C12),C12>0,C12<=Settings!$B$7),"Clear","Unchecked")) -> Unchecked
A13: C007 | D13: Unchecked | E13: Unchecked | F13: Unchecked | G13: Unchecked | H13: Unchecked | I13: Unchecked | K13: =IF(OR(COUNTIF(D13:I13,"No")>0,LEN(TRIM(J13))>0),"Blocked",IF(AND(COUNTIF(D13:I13,"Yes")=6,LEN(TRIM(B13))>0,ISNUMBER(C13),C13>0,C13<=Settings!$B$7),"Clear","Unchecked")) -> Unchecked
A14: C008 | D14: Unchecked | E14: Unchecked | F14: Unchecked | G14: Unchecked | H14: Unchecked | I14: Unchecked | K14: =IF(OR(COUNTIF(D14:I14,"No")>0,LEN(TRIM(J14))>0),"Blocked",IF(AND(COUNTIF(D14:I14,"Yes")=6,LEN(TRIM(B14))>0,ISNUMBER(C14),C14>0,C14<=Settings!$B$7),"Clear","Unchecked")) -> Unchecked
A15: C009 | D15: Unchecked | E15: Unchecked | F15: Unchecked | G15: Unchecked | H15: Unchecked | I15: Unchecked | K15: =IF(OR(COUNTIF(D15:I15,"No")>0,LEN(TRIM(J15))>0),"Blocked",IF(AND(COUNTIF(D15:I15,"Yes")=6,LEN(TRIM(B15))>0,ISNUMBER(C15),C15>0,C15<=Settings!$B$7),"Clear","Unchecked")) -> Unchecked
A16: C010 | D16: Unchecked | E16: Unchecked | F16: Unchecked | G16: Unchecked | H16: Unchecked | I16: Unchecked | K16: =IF(OR(COUNTIF(D16:I16,"No")>0,LEN(TRIM(J16))>0),"Blocked",IF(AND(COUNTIF(D16:I16,"Yes")=6,LEN(TRIM(B16))>0,ISNUMBER(C16),C16>0,C16<=Settings!$B$7),"Clear","Unchecked")) -> Unchecked
A17: C011 | D17: Unchecked | E17: Unchecked | F17: Unchecked | G17: Unchecked | H17: Unchecked | I17: Unchecked | K17: =IF(OR(COUNTIF(D17:I17,"No")>0,LEN(TRIM(J17))>0),"Blocked",IF(AND(COUNTIF(D17:I17,"Yes")=6,LEN(TRIM(B17))>0,ISNUMBER(C17),C17>0,C17<=Settings!$B$7),"Clear","Unchecked")) -> Unchecked
A18: C012 | D18: Unchecked | E18: Unchecked | F18: Unchecked | G18: Unchecked | H18: Unchecked | I18: Unchecked | K18: =IF(OR(COUNTIF(D18:I18,"No")>0,LEN(TRIM(J18))>0),"Blocked",IF(AND(COUNTIF(D18:I18,"Yes")=6,LEN(TRIM(B18))>0,ISNUMBER(C18),C18>0,C18<=Settings!$B$7),"Clear","Unchecked")) -> Unchecked
... A56: C050 | D56: Unchecked | E56: Unchecked | F56: Unchecked | G56: Unchecked | H56: Unchecked | I56: Unchecked | K56: =IF(OR(COUNTIF(D56:I56,"No")>0,LEN(TRIM(J56))>0),"Blocked",IF(AND(COUNTIF(D56:I56,"Yes")=6,LEN(TRIM(B56))>0,ISNUMBER(C56),C56>0,C56<=Settings!$B$7),"Clear","Unchecked")) -> Unchecked

Sheet Actuals
A1: 04 Record measured results
A3: Enter signed annual changes, not forecast values. Positive means released time / lower cash spend. Store fixed measurements, a period, evidence and verification; forecasts never overwrite these.
A5: =IFERROR(HYPERLINK("#'Start'!A1","← Start"),"← Start") -> ← Start
A6: Case ID | B6: Measurement basis | C6: Period start | D6: Period end | E6: Business hours saved / year | F6: Specialist hours saved / year | G6: Recurring cash change €/year | H6: Labor-value change €/year • excludes cash | I6: Measurement evidence | J6: Verified by | K6: Verification date | L6: Normalization / comparison basis | M6: Measurement status
A7: C001 | M7: =IF(AND(OR(B7="Full-year actual",B7="Annualized measurement"),COUNT(C7:H7)=6,C7>0,D7>=C7,D7<=Settings!$B$7,OR(B7="Annualized measurement",D7-C7+1>=365),LEN(TRIM(I7))>0,LEN(TRIM(J7))>0,ISNUMBER(K7),K7>=D7,K7<=Settings!$B$7,LEN(TRIM(L7))>0),"Ready","Measurements incomplete") -> Measurements incomplete
A8: C002 | M8: =IF(AND(OR(B8="Full-year actual",B8="Annualized measurement"),COUNT(C8:H8)=6,C8>0,D8>=C8,D8<=Settings!$B$7,OR(B8="Annualized measurement",D8-C8+1>=365),LEN(TRIM(I8))>0,LEN(TRIM(J8))>0,ISNUMBER(K8),K8>=D8,K8<=Settings!$B$7,LEN(TRIM(L8))>0),"Ready","Measurements incomplete") -> Measurements incomplete
A9: C003 | M9: =IF(AND(OR(B9="Full-year actual",B9="Annualized measurement"),COUNT(C9:H9)=6,C9>0,D9>=C9,D9<=Settings!$B$7,OR(B9="Annualized measurement",D9-C9+1>=365),LEN(TRIM(I9))>0,LEN(TRIM(J9))>0,ISNUMBER(K9),K9>=D9,K9<=Settings!$B$7,LEN(TRIM(L9))>0),"Ready","Measurements incomplete") -> Measurements incomplete
A10: C004 | M10: =IF(AND(OR(B10="Full-year actual",B10="Annualized measurement"),COUNT(C10:H10)=6,C10>0,D10>=C10,D10<=Settings!$B$7,OR(B10="Annualized measurement",D10-C10+1>=365),LEN(TRIM(I10))>0,LEN(TRIM(J10))>0,ISNUMBER(K10),K10>=D10,K10<=Settings!$B$7,LEN(TRIM(L10))>0),"Ready","Measurements incomplete") -> Measurements incomplete
A11: C005 | M11: =IF(AND(OR(B11="Full-year actual",B11="Annualized measurement"),COUNT(C11:H11)=6,C11>0,D11>=C11,D11<=Settings!$B$7,OR(B11="Annualized measurement",D11-C11+1>=365),LEN(TRIM(I11))>0,LEN(TRIM(J11))>0,ISNUMBER(K11),K11>=D11,K11<=Settings!$B$7,LEN(TRIM(L11))>0),"Ready","Measurements incomplete") -> Measurements incomplete
A12: C006 | M12: =IF(AND(OR(B12="Full-year actual",B12="Annualized measurement"),COUNT(C12:H12)=6,C12>0,D12>=C12,D12<=Settings!$B$7,OR(B12="Annualized measurement",D12-C12+1>=365),LEN(TRIM(I12))>0,LEN(TRIM(J12))>0,ISNUMBER(K12),K12>=D12,K12<=Settings!$B$7,LEN(TRIM(L12))>0),"Ready","Measurements incomplete") -> Measurements incomplete
A13: C007 | M13: =IF(AND(OR(B13="Full-year actual",B13="Annualized measurement"),COUNT(C13:H13)=6,C13>0,D13>=C13,D13<=Settings!$B$7,OR(B13="Annualized measurement",D13-C13+1>=365),LEN(TRIM(I13))>0,LEN(TRIM(J13))>0,ISNUMBER(K13),K13>=D13,K13<=Settings!$B$7,LEN(TRIM(L13))>0),"Ready","Measurements incomplete") -> Measurements incomplete
A14: C008 | M14: =IF(AND(OR(B14="Full-year actual",B14="Annualized measurement"),COUNT(C14:H14)=6,C14>0,D14>=C14,D14<=Settings!$B$7,OR(B14="Annualized measurement",D14-C14+1>=365),LEN(TRIM(I14))>0,LEN(TRIM(J14))>0,ISNUMBER(K14),K14>=D14,K14<=Settings!$B$7,LEN(TRIM(L14))>0),"Ready","Measurements incomplete") -> Measurements incomplete
A15: C009 | M15: =IF(AND(OR(B15="Full-year actual",B15="Annualized measurement"),COUNT(C15:H15)=6,C15>0,D15>=C15,D15<=Settings!$B$7,OR(B15="Annualized measurement",D15-C15+1>=365),LEN(TRIM(I15))>0,LEN(TRIM(J15))>0,ISNUMBER(K15),K15>=D15,K15<=Settings!$B$7,LEN(TRIM(L15))>0),"Ready","Measurements incomplete") -> Measurements incomplete
